Workbook

Sheet Input Barang
A1: No | B1: Kode Barang | C1: Tanggal Masuk
A2: =IF(B2="","",ROW()-1) | C2: =IF(B2="","",IF(C2="",NOW(),C2))
A3: =IF(B3="","",ROW()-1) | C3: =IF(B3="","",IF(C3="",NOW(),C3))
A4: =IF(B4="","",ROW()-1) | C4: =IF(B4="","",IF(C4="",NOW(),C4))
A5: =IF(B5="","",ROW()-1) | C5: =IF(B5="","",IF(C5="",NOW(),C5))
A6: =IF(B6="","",ROW()-1) | C6: =IF(B6="","",IF(C6="",NOW(),C6))
A7: =IF(B7="","",ROW()-1) | C7: =IF(B7="","",IF(C7="",NOW(),C7))
A8: =IF(B8="","",ROW()-1) | C8: =IF(B8="","",IF(C8="",NOW(),C8))
A9: =IF(B9="","",ROW()-1) | C9: =IF(B9="","",IF(C9="",NOW(),C9))
A10: =IF(B10="","",ROW()-1) | C10: =IF(B10="","",IF(C10="",NOW(),C10))
A11: =IF(B11="","",ROW()-1) | C11: =IF(B11="","",IF(C11="",NOW(),C11))
A12: =IF(B12="","",ROW()-1) | C12: =IF(B12="","",IF(C12="",NOW(),C12))
A13: =IF(B13="","",ROW()-1) | C13: =IF(B13="","",IF(C13="",NOW(),C13))
... A1000: =IF(B1000="","",ROW()-1) | C1000: =IF(B1000="","",IF(C1000="",NOW(),C1000))

Sheet Output Agus
A1: No | B1: Kode Barang | C1: Tanggal Keluar
A2: =IF(B2="","",ROW()-1) | C2: =IF(B2="","",IF(C2="",NOW(),C2))
A3: =IF(B3="","",ROW()-1) | C3: =IF(B3="","",IF(C3="",NOW(),C3))
A4: =IF(B4="","",ROW()-1) | C4: =IF(B4="","",IF(C4="",NOW(),C4))
A5: =IF(B5="","",ROW()-1) | C5: =IF(B5="","",IF(C5="",NOW(),C5))
A6: =IF(B6="","",ROW()-1) | C6: =IF(B6="","",IF(C6="",NOW(),C6))
A7: =IF(B7="","",ROW()-1) | C7: =IF(B7="","",IF(C7="",NOW(),C7))
A8: =IF(B8="","",ROW()-1) | C8: =IF(B8="","",IF(C8="",NOW(),C8))
A9: =IF(B9="","",ROW()-1) | C9: =IF(B9="","",IF(C9="",NOW(),C9))
A10: =IF(B10="","",ROW()-1) | C10: =IF(B10="","",IF(C10="",NOW(),C10))
A11: =IF(B11="","",ROW()-1) | C11: =IF(B11="","",IF(C11="",NOW(),C11))
A12: =IF(B12="","",ROW()-1) | C12: =IF(B12="","",IF(C12="",NOW(),C12))
A13: =IF(B13="","",ROW()-1) | C13: =IF(B13="","",IF(C13="",NOW(),C13))
... A1000: =IF(B1000="","",ROW()-1) | C1000: =IF(B1000="","",IF(C1000="",NOW(),C1000))

Sheet Output Rexa
A1: No | B1: Kode Barang | C1: Tanggal Keluar
A2: =IF(B2="","",ROW()-1) | C2: =IF(B2="","",IF(C2="",NOW(),C2))
A3: =IF(B3="","",ROW()-1) | C3: =IF(B3="","",IF(C3="",NOW(),C3))
A4: =IF(B4="","",ROW()-1) | C4: =IF(B4="","",IF(C4="",NOW(),C4))
A5: =IF(B5="","",ROW()-1) | C5: =IF(B5="","",IF(C5="",NOW(),C5))
A6: =IF(B6="","",ROW()-1) | C6: =IF(B6="","",IF(C6="",NOW(),C6))
A7: =IF(B7="","",ROW()-1) | C7: =IF(B7="","",IF(C7="",NOW(),C7))
A8: =IF(B8="","",ROW()-1) | C8: =IF(B8="","",IF(C8="",NOW(),C8))
A9: =IF(B9="","",ROW()-1) | C9: =IF(B9="","",IF(C9="",NOW(),C9))
A10: =IF(B10="","",ROW()-1) | C10: =IF(B10="","",IF(C10="",NOW(),C10))
A11: =IF(B11="","",ROW()-1) | C11: =IF(B11="","",IF(C11="",NOW(),C11))
A12: =IF(B12="","",ROW()-1) | C12: =IF(B12="","",IF(C12="",NOW(),C12))
A13: =IF(B13="","",ROW()-1) | C13: =IF(B13="","",IF(C13="",NOW(),C13))
... A1000: =IF(B1000="","",ROW()-1) | C1000: =IF(B1000="","",IF(C1000="",NOW(),C1000))

Sheet Rekap
A1: REKAP KELUAR MASUK BARANG
A3: Keterangan | B3: Jumlah
A4: Total Barang Masuk (Input) | B4: =COUNTA('Input Barang'!B2:B1000)
A5: Total Keluar - Agus | B5: =COUNTA('Output Agus'!B2:B1000)
A6: Total Keluar - Rexa | B6: =COUNTA('Output Rexa'!B2:B1000)
A7: Total Keluar (Agus + Rexa) | B7: =B5+B6
A8: Sisa Stok (Input - Keluar) | B8: =B4-B7
A10: REKAP PER KODE BARANG
A11: Kode Barang | B11: Input | C11: Keluar Agus | D11: Keluar Rexa | E11: Sisa
A12: =IFERROR(INDEX('Input Barang'!$B$2:$B$1000,1),"") | B12: =IF(A12="","",COUNTIF('Input Barang'!$B$2:$B$1000,A12)) | C12: =IF(A12="","",COUNTIF('Output Agus'!$B$2:$B$1000,A12)) | D12: =IF(A12="","",COUNTIF('Output Rexa'!$B$2:$B$1000,A12)) | E12: =IF(A12="","",B12-C12-D12)
A13: =IFERROR(INDEX('Input Barang'!$B$2:$B$1000,2),"") | B13: =IF(A13="","",COUNTIF('Input Barang'!$B$2:$B$1000,A13)) | C13: =IF(A13="","",COUNTIF('Output Agus'!$B$2:$B$1000,A13)) | D13: =IF(A13="","",COUNTIF('Output Rexa'!$B$2:$B$1000,A13)) | E13: =IF(A13="","",B13-C13-D13)
A14: =IFERROR(INDEX('Input Barang'!$B$2:$B$1000,3),"") | B14: =IF(A14="","",COUNTIF('Input Barang'!$B$2:$B$1000,A14)) | C14: =IF(A14="","",COUNTIF('Output Agus'!$B$2:$B$1000,A14)) | D14: =IF(A14="","",COUNTIF('Output Rexa'!$B$2:$B$1000,A14)) | E14: =IF(A14="","",B14-C14-D14)
A15: =IFERROR(INDEX('Input Barang'!$B$2:$B$1000,4),"") | B15: =IF(A15="","",COUNTIF('Input Barang'!$B$2:$B$1000,A15)) | C15: =IF(A15="","",COUNTIF('Output Agus'!$B$2:$B$1000,A15)) | D15: =IF(A15="","",COUNTIF('Output Rexa'!$B$2:$B$1000,A15)) | E15: =IF(A15="","",B15-C15-D15)
A16: =IFERROR(INDEX('Input Barang'!$B$2:$B$1000,5),"") | B16: =IF(A16="","",COUNTIF('Input Barang'!$B$2:$B$1000,A16)) | C16: =IF(A16="","",COUNTIF('Output Agus'!$B$2:$B$1000,A16)) | D16: =IF(A16="","",COUNTIF('Output Rexa'!$B$2:$B$1000,A16)) | E16: =IF(A16="","",B16-C16-D16)
A17: =IFERROR(INDEX('Input Barang'!$B$2:$B$1000,6),"") | B17: =IF(A17="","",COUNTIF('Input Barang'!$B$2:$B$1000,A17)) | C17: =IF(A17="","",COUNTIF('Output Agus'!$B$2:$B$1000,A17)) | D17: =IF(A17="","",COUNTIF('Output Rexa'!$B$2:$B$1000,A17)) | E17: =IF(A17="","",B17-C17-D17)
A18: =IFERROR(INDEX('Input Barang'!$B$2:$B$1000,7),"") | B18: =IF(A18="","",COUNTIF('Input Barang'!$B$2:$B$1000,A18)) | C18: =IF(A18="","",COUNTIF('Output Agus'!$B$2:$B$1000,A18)) | D18: =IF(A18="","",COUNTIF('Output Rexa'!$B$2:$B$1000,A18)) | E18: =IF(A18="","",B18-C18-D18)
A19: =IFERROR(INDEX('Input Barang'!$B$2:$B$1000,8),"") | B19: =IF(A19="","",COUNTIF('Input Barang'!$B$2:$B$1000,A19)) | C19: =IF(A19="","",COUNTIF('Output Agus'!$B$2:$B$1000,A19)) | D19: =IF(A19="","",COUNTIF('Output Rexa'!$B$2:$B$1000,A19)) | E19: =IF(A19="","",B19-C19-D19)
A20: =IFERROR(INDEX('Input Barang'!$B$2:$B$1000,9),"") | B20: =IF(A20="","",COUNTIF('Input Barang'!$B$2:$B$1000,A20)) | C20: =IF(A20="","",COUNTIF('Output Agus'!$B$2:$B$1000,A20)) | D20: =IF(A20="","",COUNTIF('Output Rexa'!$B$2:$B$1000,A20)) | E20: =IF(A20="","",B20-C20-D20)
A21: =IFERROR(INDEX('Input Barang'!$B$2:$B$1000,10),"") | B21: =IF(A21="","",COUNTIF('Input Barang'!$B$2:$B$1000,A21)) | C21: =IF(A21="","",COUNTIF('Output Agus'!$B$2:$B$1000,A21)) | D21: =IF(A21="","",COUNTIF('Output Rexa'!$B$2:$B$1000,A21)) | E21: =IF(A21="","",B21-C21-D21)
A22: =IFERROR(INDEX('Input Barang'!$B$2:$B$1000,11),"") | B22: =IF(A22="","",COUNTIF('Input Barang'!$B$2:$B$1000,A22)) | C22: =IF(A22="","",COUNTIF('Output Agus'!$B$2:$B$1000,A22)) | D22: =IF(A22="","",COUNTIF('Output Rexa'!$B$2:$B$1000,A22)) | E22: =IF(A22="","",B22-C22-D22)
A23: =IFERROR(INDEX('Input Barang'!$B$2:$B$1000,12),"") | B23: =IF(A23="","",COUNTIF('Input Barang'!$B$2:$B$1000,A23)) | C23: =IF(A23="","",COUNTIF('Output Agus'!$B$2:$B$1000,A23)) | D23: =IF(A23="","",COUNTIF('Output Rexa'!$B$2:$B$1000,A23)) | E23: =IF(A23="","",B23-C23-D23)
A24: =IFERROR(INDEX('Input Barang'!$B$2:$B$1000,13),"") | B24: =IF(A24="","",COUNTIF('Input Barang'!$B$2:$B$1000,A24)) | C24: =IF(A24="","",COUNTIF('Output Agus'!$B$2:$B$1000,A24)) | D24: =IF(A24="","",COUNTIF('Output Rexa'!$B$2:$B$1000,A24)) | E24: =IF(A24="","",B24-C24-D24)
A25: =IFERROR(INDEX('Input Barang'!$B$2:$B$1000,14),"") | B25: =IF(A25="","",COUNTIF('Input Barang'!$B$2:$B$1000,A25)) | C25: =IF(A25="","",COUNTIF('Output Agus'!$B$2:$B$1000,A25)) | D25: =IF(A25="","",COUNTIF('Output Rexa'!$B$2:$B$1000,A25)) | E25: =IF(A25="","",B25-C25-D25)
A26: =IFERROR(INDEX('Input Barang'!$B$2:$B$1000,15),"") | B26: =IF(A26="","",COUNTIF('Input Barang'!$B$2:$B$1000,A26)) | C26: =IF(A26="","",COUNTIF('Output Agus'!$B$2:$B$1000,A26)) | D26: =IF(A26="","",COUNTIF('Output Rexa'!$B$2:$B$1000,A26)) | E26: =IF(A26="","",B26-C26-D26)
A27: =IFERROR(INDEX('Input Barang'!$B$2:$B$1000,16),"") | B27: =IF(A27="","",COUNTIF('Input Barang'!$B$2:$B$1000,A27)) | C27: =IF(A27="","",COUNTIF('Output Agus'!$B$2:$B$1000,A27)) | D27: =IF(A27="","",COUNTIF('Output Rexa'!$B$2:$B$1000,A27)) | E27: =IF(A27="","",B27-C27-D27)
A28: =IFERROR(INDEX('Input Barang'!$B$2:$B$1000,17),"") | B28: =IF(A28="","",COUNTIF('Input Barang'!$B$2:$B$1000,A28)) | C28: =IF(A28="","",COUNTIF('Output Agus'!$B$2:$B$1000,A28)) | D28: =IF(A28="","",COUNTIF('Output Rexa'!$B$2:$B$1000,A28)) | E28: =IF(A28="","",B28-C28-D28)
A29: =IFERROR(INDEX('Input Barang'!$B$2:$B$1000,18),"") | B29: =IF(A29="","",COUNTIF('Input Barang'!$B$2:$B$1000,A29)) | C29: =IF(A29="","",COUNTIF('Output Agus'!$B$2:$B$1000,A29)) | D29: =IF(A29="","",COUNTIF('Output Rexa'!$B$2:$B$1000,A29)) | E29: =IF(A29="","",B29-C29-D29)
A30: =IFERROR(INDEX('Input Barang'!$B$2:$B$1000,19),"") | B30: =IF(A30="","",COUNTIF('Input Barang'!$B$2:$B$1000,A30)) | C30: =IF(A30="","",COUNTIF('Output Agus'!$B$2:$B$1000,A30)) | D30: =IF(A30="","",COUNTIF('Output Rexa'!$B$2:$B$1000,A30)) | E30: =IF(A30="","",B30-C30-D30)
A31: =IFERROR(INDEX('Input Barang'!$B$2:$B$1000,20),"") | B31: =IF(A31="","",COUNTIF('Input Barang'!$B$2:$B$1000,A31)) | C31: =IF(A31="","",COUNTIF('Output Agus'!$B$2:$B$1000,A31)) | D31: =IF(A31="","",COUNTIF('Output Rexa'!$B$2:$B$1000,A31)) | E31: =IF(A31="","",B31-C31-D31)
A32: =IFERROR(INDEX('Input Barang'!$B$2:$B$1000,21),"") | B32: =IF(A32="","",COUNTIF('Input Barang'!$B$2:$B$1000,A32)) | C32: =IF(A32="","",COUNTIF('Output Agus'!$B$2:$B$1000,A32)) | D32: =IF(A32="","",COUNTIF('Output Rexa'!$B$2:$B$1000,A32)) | E32: =IF(A32="","",B32-C32-D32)
A33: =IFERROR(INDEX('Input Barang'!$B$2:$B$1000,22),"") | B33: =IF(A33="","",COUNTIF('Input Barang'!$B$2:$B$1000,A33)) | C33: =IF(A33="","",COUNTIF('Output Agus'!$B$2:$B$1000,A33)) | D33: =IF(A33="","",COUNTIF('Output Rexa'!$B$2:$B$1000,A33)) | E33: =IF(A33="","",B33-C33-D33)
A34: =IFERROR(INDEX('Input Barang'!$B$2:$B$1000,23),"") | B34: =IF(A34="","",COUNTIF('Input Barang'!$B$2:$B$1000,A34)) | C34: =IF(A34="","",COUNTIF('Output Agus'!$B$2:$B$1000,A34)) | D34: =IF(A34="","",COUNTIF('Output Rexa'!$B$2:$B$1000,A34)) | E34: =IF(A34="","",B34-C34-D34)
A35: =IFERROR(INDEX('Input Barang'!$B$2:$B$1000,24),"") | B35: =IF(A35="","",COUNTIF('Input Barang'!$B$2:$B$1000,A35)) | C35: =IF(A35="","",COUNTIF('Output Agus'!$B$2:$B$1000,A35)) | D35: =IF(A35="","",COUNTIF('Output Rexa'!$B$2:$B$1000,A35)) | E35: =IF(A35="","",B35-C35-D35)
A36: =IFERROR(INDEX('Input Barang'!$B$2:$B$1000,25),"") | B36: =IF(A36="","",COUNTIF('Input Barang'!$B$2:$B$1000,A36)) | C36: =IF(A36="","",COUNTIF('Output Agus'!$B$2:$B$1000,A36)) | D36: =IF(A36="","",COUNTIF('Output Rexa'!$B$2:$B$1000,A36)) | E36: =IF(A36="","",B36-C36-D36)
A37: =IFERROR(INDEX('Input Barang'!$B$2:$B$1000,26),"") | B37: =IF(A37="","",COUNTIF('Input Barang'!$B$2:$B$1000,A37)) | C37: =IF(A37="","",COUNTIF('Output Agus'!$B$2:$B$1000,A37)) | D37: =IF(A37="","",COUNTIF('Output Rexa'!$B$2:$B$1000,A37)) | E37: =IF(A37="","",B37-C37-D37)
A38: =IFERROR(INDEX('Input Barang'!$B$2:$B$1000,27),"") | B38: =IF(A38="","",COUNTIF('Input Barang'!$B$2:$B$1000,A38)) | C38: =IF(A38="","",COUNTIF('Output Agus'!$B$2:$B$1000,A38)) | D38: =IF(A38="","",COUNTIF('Output Rexa'!$B$2:$B$1000,A38)) | E38: =IF(A38="","",B38-C38-D38)
A39: =IFERROR(INDEX('Input Barang'!$B$2:$B$1000,28),"") | B39: =IF(A39="","",COUNTIF('Input Barang'!$B$2:$B$1000,A39)) | C39: =IF(A39="","",COUNTIF('Output Agus'!$B$2:$B$1000,A39)) | D39: =IF(A39="","",COUNTIF('Output Rexa'!$B$2:$B$1000,A39)) | E39: =IF(A39="","",B39-C39-D39)
A40: =IFERROR(INDEX('Input Barang'!$B$2:$B$1000,29),"") | B40: =IF(A40="","",COUNTIF('Input Barang'!$B$2:$B$1000,A40)) | C40: =IF(A40="","",COUNTIF('Output Agus'!$B$2:$B$1000,A40)) | D40: =IF(A40="","",COUNTIF('Output Rexa'!$B$2:$B$1000,A40)) | E40: =IF(A40="","",B40-C40-D40)
A41: =IFERROR(INDEX('Input Barang'!$B$2:$B$1000,30),"") | B41: =IF(A41="","",COUNTIF('Input Barang'!$B$2:$B$1000,A41)) | C41: =IF(A41="","",COUNTIF('Output Agus'!$B$2:$B$1000,A41)) | D41: =IF(A41="","",COUNTIF('Output Rexa'!$B$2:$B$1000,A41)) | E41: =IF(A41="","",B41-C41-D41)
A42: =IFERROR(INDEX('Input Barang'!$B$2:$B$1000,31),"") | B42: =IF(A42="","",COUNTIF('Input Barang'!$B$2:$B$1000,A42)) | C42: =IF(A42="","",COUNTIF('Output Agus'!$B$2:$B$1000,A42)) | D42: =IF(A42="","",COUNTIF('Output Rexa'!$B$2:$B$1000,A42)) | E42: =IF(A42="","",B42-C42-D42)
...
